<?xml version="1.0"?>
<!--
  RoboCot M1013 + Robotiq Hand-E + Wrist RGB-D Camera
  Gazebo Ignition Fortress compatible (ros2_control + gz_ros2_control)

  Ported from:
    - robocob_ws_sim/doosan-robot/dsr_description (M1013 arm)
    - robocob_ws_sim/robotiq/robotiq_description (Hand-E gripper)
    - harvesting_ws mybot.urdf.xacro (camera + ros2_control pattern)
-->
<robot xmlns:xacro="http://www.ros.org/wiki/xacro" name="m1013_robocot">
	<xacro:arg name="controllers_yaml" default=""/>

	<!-- ==================== World ==================== -->
	<link name="world"/>

	<joint name="world_fixed" type="fixed">
		<origin xyz="0 0 0" rpy="0 0 0"/>
		<parent link="world"/>
		<child link="base_0"/>
	</joint>

	<!-- ==================== M1013 Arm ==================== -->
	<!-- Base (link0) -->
	<link name="base_0">
		<inertial>
			<mass value="4.12"/>
			<origin xyz="-3.4e-05 -0.004815 0.048482"/>
			<inertia ixx="0.016331" ixy="-6.4837e-06" ixz="2.0048e-06" iyy="0.014945" iyz="-0.00051686" izz="0.022577"/>
		</inertial>
		<visual>
			<origin rpy="0 0 0" xyz="0 0 0"/>
			<geometry>
				<mesh filename="package://robot_arm/meshes/m1013_blue/MF1013_0_0.dae" scale="0.001 0.001 0.001"/>
			</geometry>
		</visual>
		<collision>
			<origin rpy="0 0 0" xyz="0 0 0"/>
			<geometry>
				<mesh filename="package://robot_arm/meshes/m1013_collision/MF1013_0_0.dae" scale="0.001 0.001 0.001"/>
			</geometry>
		</collision>
	</link>

	<!-- Joint 1 (base rotation) -->
	<joint name="joint1" type="revolute">
		<parent link="base_0"/>
		<child link="link1"/>
		<origin rpy="0 0 0" xyz="0 0 0.1525"/>
		<axis xyz="0 0 1"/>
		<limit effort="346" lower="-6.2832" upper="6.2832" velocity="2.0944"/>
		<dynamics friction="0"/>
	</joint>
	<link name="link1">
		<inertial>
			<mass value="7.8"/>
			<origin xyz="0.000119 0.0428 -0.006383"/>
			<inertia ixx="0.04506" ixy="4.1126e-05" ixz="-5.2533e-05" iyy="0.029679" iyz="-0.0019959" izz="0.047056"/>
		</inertial>
		<visual>
			<origin rpy="0 0 0" xyz="0 0 0"/>
			<geometry>
				<mesh filename="package://robot_arm/meshes/m1013_blue/MF1013_1_0.dae" scale="0.001 0.001 0.001"/>
			</geometry>
		</visual>
		<collision>
			<origin rpy="0 0 0" xyz="0 0 0"/>
			<geometry>
				<mesh filename="package://robot_arm/meshes/m1013_collision/MF1013_1_0.dae" scale="0.001 0.001 0.001"/>
			</geometry>
		</collision>
	</link>

	<!-- Joint 2 (shoulder) -->
	<joint name="joint2" type="revolute">
		<parent link="link1"/>
		<child link="link2"/>
		<origin rpy="0 -1.571 -1.571" xyz="0 0.0345 0"/>
		<axis xyz="0 0 1"/>
		<limit effort="346" lower="-6.2832" upper="6.2832" velocity="2.0944"/>
		<dynamics friction="0"/>
	</joint>
	<link name="link2">
		<inertial>
			<mass value="10.83"/>
			<origin xyz="0.25973 -5.3e-05 0.15782"/>
			<inertia ixx="0.037586" ixy="-0.00036999" ixz="-0.0069927" iyy="0.84943" iyz="4.0201e-05" izz="0.85021"/>
		</inertial>
		<visual>
			<origin rpy="0 0 0" xyz="0 0 0"/>
			<geometry>
				<mesh filename="package://robot_arm/meshes/m1013_blue/MF1013_2_0.dae" scale="0.001 0.001 0.001"/>
			</geometry>
		</visual>
		<collision>
			<origin rpy="0 0 0" xyz="0 0 0"/>
			<geometry>
				<mesh filename="package://robot_arm/meshes/m1013_collision/MF1013_2_0.dae" scale="0.001 0.001 0.001"/>
			</geometry>
		</collision>
		<visual>
			<origin rpy="0 0 0" xyz="0 0 0"/>
			<geometry>
				<mesh filename="package://robot_arm/meshes/m1013_blue/MF1013_2_1.dae" scale="0.001 0.001 0.001"/>
			</geometry>
		</visual>
		<collision>
			<origin rpy="0 0 0" xyz="0 0 0"/>
			<geometry>
				<mesh filename="package://robot_arm/meshes/m1013_collision/MF1013_2_1.dae" scale="0.001 0.001 0.001"/>
			</geometry>
		</collision>
		<visual>
			<origin rpy="0 0 0" xyz="0 0 0"/>
			<geometry>
				<mesh filename="package://robot_arm/meshes/m1013_blue/MF1013_2_2.dae" scale="0.001 0.001 0.001"/>
			</geometry>
		</visual>
		<collision>
			<origin rpy="0 0 0" xyz="0 0 0"/>
			<geometry>
				<mesh filename="package://robot_arm/meshes/m1013_collision/MF1013_2_2.dae" scale="0.001 0.001 0.001"/>
			</geometry>
		</collision>
	</link>

	<!-- Joint 3 (elbow) -->
	<joint name="joint3" type="revolute">
		<parent link="link2"/>
		<child link="link3"/>
		<origin rpy="0 0 1.571" xyz="0.62 0 0"/>
		<axis xyz="0 0 1"/>
		<limit effort="163" lower="-2.7925" upper="2.7925" velocity="3.1416"/>
		<dynamics friction="0"/>
	</joint>
	<link name="link3">
		<inertial>
			<mass value="3.68"/>
			<origin xyz="-1.5e-05 -0.006702 0.044608"/>
			<inertia ixx="0.018748" ixy="7.8071e-06" ixz="-5.0324e-06" iyy="0.018972" iyz="-0.00099342" izz="0.011502"/>
		</inertial>
		<visual>
			<origin rpy="0 0 0" xyz="0 0 0"/>
			<geometry>
				<mesh filename="package://robot_arm/meshes/m1013_blue/MF1013_3_0.dae" scale="0.001 0.001 0.001"/>
			</geometry>
		</visual>
		<collision>
			<origin rpy="0 0 0" xyz="0 0 0"/>
			<geometry>
				<mesh filename="package://robot_arm/meshes/m1013_collision/MF1013_3_0.dae" scale="0.001 0.001 0.001"/>
			</geometry>
		</collision>
	</link>

	<!-- Joint 4 (wrist 1) -->
	<joint name="joint4" type="revolute">
		<parent link="link3"/>
		<child link="link4"/>
		<origin rpy="1.571 0 0" xyz="0 -0.559 0"/>
		<axis xyz="0 0 1"/>
		<limit effort="50" lower="-6.2832" upper="6.2832" velocity="3.927"/>
		<dynamics friction="0"/>
	</joint>
	<link name="link4">
		<inertial>
			<mass value="3.82"/>
			<origin xyz="7.1e-05 0.091879 -0.18252"/>
			<inertia ixx="0.19063" ixy="-1.8037e-05" ixz="-3.8576e-05" iyy="0.17268" iyz="-0.052996" izz="0.030386"/>
		</inertial>
		<visual>
			<origin rpy="0 0 0" xyz="0 0 0"/>
			<geometry>
				<mesh filename="package://robot_arm/meshes/m1013_blue/MF1013_4_0.dae" scale="0.001 0.001 0.001"/>
			</geometry>
		</visual>
		<collision>
			<origin rpy="0 0 0" xyz="0 0 0"/>
			<geometry>
				<mesh filename="package://robot_arm/meshes/m1013_collision/MF1013_4_0.dae" scale="0.001 0.001 0.001"/>
			</geometry>
		</collision>
		<visual>
			<origin rpy="0 0 0" xyz="0 0 0"/>
			<geometry>
				<mesh filename="package://robot_arm/meshes/m1013_blue/MF1013_4_1.dae" scale="0.001 0.001 0.001"/>
			</geometry>
		</visual>
		<collision>
			<origin rpy="0 0 0" xyz="0 0 0"/>
			<geometry>
				<mesh filename="package://robot_arm/meshes/m1013_collision/MF1013_4_1.dae" scale="0.001 0.001 0.001"/>
			</geometry>
		</collision>
	</link>

	<!-- Joint 5 (wrist 2) -->
	<joint name="joint5" type="revolute">
		<parent link="link4"/>
		<child link="link5"/>
		<origin rpy="-1.571 0 0" xyz="0 0 0"/>
		<axis xyz="0 0 1"/>
		<limit effort="50" lower="-6.2832" upper="6.2832" velocity="3.927"/>
		<dynamics friction="0"/>
	</joint>
	<link name="link5">
		<inertial>
			<mass value="2.82"/>
			<origin xyz="-0.000273 0.003651 0.032088"/>
			<inertia ixx="0.015583" ixy="2.135e-05" ixz="-5.1895e-06" iyy="0.011519" iyz="0.00042553" izz="0.0088671"/>
		</inertial>
		<visual>
			<origin rpy="0 0 0" xyz="0 0 0"/>
			<geometry>
				<mesh filename="package://robot_arm/meshes/m1013_blue/MF1013_5_0.dae" scale="0.001 0.001 0.001"/>
			</geometry>
		</visual>
		<collision>
			<origin rpy="0 0 0" xyz="0 0 0"/>
			<geometry>
				<mesh filename="package://robot_arm/meshes/m1013_collision/MF1013_5_0.dae" scale="0.001 0.001 0.001"/>
			</geometry>
		</collision>
	</link>

	<!-- Joint 6 (wrist 3 / tool flange) -->
	<joint name="joint6" type="revolute">
		<parent link="link5"/>
		<child link="link6"/>
		<origin rpy="1.571 0 0" xyz="0 -0.121 0"/>
		<axis xyz="0 0 1"/>
		<limit effort="50" lower="-6.2832" upper="6.2832" velocity="3.927"/>
		<dynamics friction="0"/>
	</joint>
	<link name="link6">
		<inertial>
			<mass value="1.16"/>
			<origin xyz="-0.000292 7e-06 -0.0539"/>
			<inertia ixx="0.0048282" ixy="4.1298e-06" ixz="6.9879e-06" iyy="0.0059519" iyz="4.252e-06" izz="0.0061263"/>
		</inertial>
		<visual>
			<origin rpy="0 0 0" xyz="0 0 0"/>
			<geometry>
				<mesh filename="package://robot_arm/meshes/m1013_blue/MF1013_6_0.dae" scale="0.001 0.001 0.001"/>
			</geometry>
		</visual>
		<collision>
			<origin rpy="0 0 0" xyz="0 0 0"/>
			<geometry>
				<mesh filename="package://robot_arm/meshes/m1013_collision/MF1013_6_0.dae" scale="0.001 0.001 0.001"/>
			</geometry>
		</collision>
	</link>

	<!-- ==================== Tool Flange Frame ==================== -->
	<joint name="tool0_joint" type="fixed">
		<parent link="link6"/>
		<child link="tool0"/>
		<origin xyz="0 0 0" rpy="0 0 0"/>
	</joint>
	<link name="tool0"/>

	<!-- ==================== Robotiq Hand-E Gripper ==================== -->
	<!-- Fixed mount: Hand-E base attaches to tool0 (tool flange) -->
	<joint name="robotiq_hande_base_joint" type="fixed">
		<parent link="tool0"/>
		<child link="hand_e_link"/>
		<origin xyz="0 0 0" rpy="0 0 0"/>
	</joint>

	<link name="hand_e_link">
		<inertial>
			<origin rpy="0 0 0" xyz="0 0 0.04607"/>
			<mass value="0.86387"/>
			<inertia ixx="1.01756e-03" ixy="0" ixz="2.235e-06" iyy="1.028041e-03" iyz="0" izz="4.8981e-04"/>
		</inertial>
		<visual>
			<origin rpy="0 0 0" xyz="0 0 0"/>
			<geometry>
				<mesh filename="package://robot_arm/meshes/hande/hande.dae" scale="1.0 1.0 1.0"/>
			</geometry>
			<material name="HandE_Dark">
				<color rgba="0.1 0.1 0.1 1.0"/>
			</material>
		</visual>
		<visual>
			<origin rpy="0 0 0" xyz="0 0 -0.0015"/>
			<geometry>
				<mesh filename="package://robot_arm/meshes/exchanger/hande_base.dae" scale="1.0 1.0 1.0"/>
			</geometry>
		</visual>
		<collision>
			<origin rpy="0 0 0" xyz="0 0 0"/>
			<geometry>
				<mesh filename="package://robot_arm/meshes/hande/hande-collision.dae" scale="1.0 1.0 1.0"/>
			</geometry>
		</collision>
	</link>

	<!-- Left finger (driven) -->
	<joint name="hande_left_finger_joint" type="prismatic">
		<parent link="hand_e_link"/>
		<child link="hande_left_finger"/>
		<origin rpy="0 0 0" xyz="0 0 0.099"/>
		<axis xyz="-1 0 0"/>
		<limit effort="130" lower="0" upper="0.025" velocity="0.15"/>
	</joint>
	<link name="hande_left_finger">
		<inertial>
			<origin rpy="0 0 0" xyz="0.02262 -0.00759 0.00738"/>
			<mass value="0.05"/>
			<inertia ixx="1e-04" ixy="0" ixz="0" iyy="1e-04" iyz="0" izz="1e-04"/>
		</inertial>
		<visual>
			<origin rpy="0 0 0" xyz="0 0 0"/>
			<geometry>
				<mesh filename="package://robot_arm/meshes/hande/finger_1.dae" scale="1.0 1.0 1.0"/>
			</geometry>
			<material name="HandE_Gray">
				<color rgba="0.4 0.4 0.4 1.0"/>
			</material>
		</visual>
		<collision>
			<origin rpy="0 0 0" xyz="0 0 0"/>
			<geometry>
				<mesh filename="package://robot_arm/meshes/hande/finger_1_collision.dae" scale="1.0 1.0 1.0"/>
			</geometry>
		</collision>
	</link>

	<!-- Right finger (mimic of left) -->
	<joint name="hande_right_finger_joint" type="prismatic">
		<parent link="hand_e_link"/>
		<child link="hande_right_finger"/>
		<origin rpy="0 0 0" xyz="0 0 0.099"/>
		<axis xyz="1 0 0"/>
		<limit effort="130" lower="0" upper="0.025" velocity="0.15"/>
		<mimic joint="hande_left_finger_joint" multiplier="1" offset="0"/>
	</joint>
	<link name="hande_right_finger">
		<inertial>
			<origin rpy="0 0 0" xyz="-0.02262 0.00759 0.00738"/>
			<mass value="0.05"/>
			<inertia ixx="1e-04" ixy="0" ixz="0" iyy="1e-04" iyz="0" izz="1e-04"/>
		</inertial>
		<visual>
			<origin rpy="0 0 0" xyz="0 0 0"/>
			<geometry>
				<mesh filename="package://robot_arm/meshes/hande/finger_2.dae" scale="1.0 1.0 1.0"/>
			</geometry>
			<material name="HandE_Gray">
				<color rgba="0.4 0.4 0.4 1.0"/>
			</material>
		</visual>
		<collision>
			<origin rpy="0 0 0" xyz="0 0 0"/>
			<geometry>
				<mesh filename="package://robot_arm/meshes/hande/finger_2_collision.dae" scale="1.0 1.0 1.0"/>
			</geometry>
		</collision>
	</link>

	<!-- TCP frame (gripper tip center) -->
	<joint name="tcp_joint" type="fixed">
		<parent link="hand_e_link"/>
		<child link="tcp"/>
		<!-- 0.099 (finger origin) + ~0.05 (finger length) = ~0.14 from hand_e_link -->
		<origin xyz="0 0 0.14" rpy="0 0 0"/>
	</joint>
	<link name="tcp">
		<visual>
			<geometry>
				<sphere radius="0.005"/>
			</geometry>
			<material name="tcp_red">
				<color rgba="1 0 0 1"/>
			</material>
		</visual>
	</link>

	<!-- ==================== Wrist-Mounted RGB-D Camera ==================== -->
	<!-- Mounted on link6 (before gripper), offset to side to avoid occlusion -->
	<joint name="camera_joint" type="fixed">
		<parent link="link6"/>
		<child link="camera_link"/>
		<origin xyz="-0.05 0 -0.02" rpy="0 -1.5708 0"/>
	</joint>
	<link name="camera_link">
		<visual>
			<geometry>
				<box size="0.02 0.03 0.02"/>
			</geometry>
			<material name="camera_black">
				<color rgba="0.1 0.1 0.1 1"/>
			</material>
		</visual>
		<collision>
			<geometry>
				<box size="0.02 0.03 0.02"/>
			</geometry>
		</collision>
		<inertial>
			<mass value="0.05"/>
			<inertia ixx="1e-6" iyy="1e-6" izz="1e-6" ixy="0" ixz="0" iyz="0"/>
		</inertial>
	</link>

	<!-- ROS optical frame convention: Z forward, X right, Y down -->
	<joint name="camera_optical_joint" type="fixed">
		<parent link="camera_link"/>
		<child link="camera_optical_frame"/>
		<origin xyz="0 0 0" rpy="-1.5708 0 -1.5708"/>
	</joint>
	<link name="camera_optical_frame"/>

	<!-- Gazebo Sim RGB-D sensor -->
	<gazebo reference="camera_link">
		<sensor type="rgbd_camera" name="wrist_rgbd_camera">
			<always_on>true</always_on>
			<update_rate>30.0</update_rate>
			<topic>camera</topic>
			<ignition_frame_id>camera_optical_frame</ignition_frame_id>
			<camera name="wrist_camera">
				<horizontal_fov>1.57</horizontal_fov>
				<image>
					<width>640</width>
					<height>480</height>
					<format>R8G8B8</format>
				</image>
				<lens>
					<intrinsics>
						<fx>277</fx>
						<fy>277</fy>
						<cx>320</cx>
						<cy>240</cy>
						<s>0</s>
					</intrinsics>
				</lens>
				<clip>
					<near>0.05</near>
					<far>3.0</far>
				</clip>
				<depth_camera>
					<clip>
						<near>0.05</near>
						<far>3.0</far>
					</clip>
				</depth_camera>
				<noise>
					<type>gaussian</type>
					<mean>0.0</mean>
					<stddev>0.007</stddev>
				</noise>
			</camera>
		</sensor>
	</gazebo>

	<!-- Gripper finger physics for grasping -->
	<gazebo reference="hande_left_finger">
		<mu1>1.0</mu1>
		<mu2>1.0</mu2>
		<kp>1000000.0</kp>
		<kd>1.0</kd>
		<minDepth>0.001</minDepth>
	</gazebo>
	<gazebo reference="hande_right_finger">
		<mu1>1.0</mu1>
		<mu2>1.0</mu2>
		<kp>1000000.0</kp>
		<kd>1.0</kd>
		<minDepth>0.001</minDepth>
	</gazebo>

	<!-- ==================== ros2_control ==================== -->
	<ros2_control name="m1013_robocot_control" type="system">
		<hardware>
			<plugin>ign_ros2_control/IgnitionSystem</plugin>
		</hardware>
		<!-- Arm joints (6-DOF revolute) -->
		<joint name="joint1">
			<command_interface name="position">
				<param name="min">-6.2832</param>
				<param name="max">6.2832</param>
			</command_interface>
			<state_interface name="position"/>
			<state_interface name="velocity"/>
		</joint>
		<joint name="joint2">
			<command_interface name="position">
				<param name="min">-6.2832</param>
				<param name="max">6.2832</param>
			</command_interface>
			<state_interface name="position"/>
			<state_interface name="velocity"/>
		</joint>
		<joint name="joint3">
			<command_interface name="position">
				<param name="min">-2.7925</param>
				<param name="max">2.7925</param>
			</command_interface>
			<state_interface name="position"/>
			<state_interface name="velocity"/>
		</joint>
		<joint name="joint4">
			<command_interface name="position">
				<param name="min">-6.2832</param>
				<param name="max">6.2832</param>
			</command_interface>
			<state_interface name="position"/>
			<state_interface name="velocity"/>
		</joint>
		<joint name="joint5">
			<command_interface name="position">
				<param name="min">-6.2832</param>
				<param name="max">6.2832</param>
			</command_interface>
			<state_interface name="position"/>
			<state_interface name="velocity"/>
		</joint>
		<joint name="joint6">
			<command_interface name="position">
				<param name="min">-6.2832</param>
				<param name="max">6.2832</param>
			</command_interface>
			<state_interface name="position"/>
			<state_interface name="velocity"/>
		</joint>
		<!-- Gripper joint (prismatic) -->
		<joint name="hande_left_finger_joint">
			<command_interface name="position">
				<param name="min">0</param>
				<param name="max">0.025</param>
			</command_interface>
			<state_interface name="position"/>
			<state_interface name="velocity"/>
		</joint>
	</ros2_control>

	<!-- ==================== Gazebo Sim ROS2 Control Plugin ==================== -->
	<gazebo>
		<plugin filename="ign_ros2_control-system" name="ign_ros2_control::IgnitionROS2ControlPlugin">
			<parameters>$(arg controllers_yaml)</parameters>
		</plugin>
	</gazebo>

</robot>
